Workbook
Name _C1: '[1]WLF Calculations'!$H$3
Name _C1: 'WLF Calculations'!$H$3
Name _C2: '[1]WLF Calculations'!$H$4
Name _C2: 'WLF Calculations'!$H$4
Name G_1: 'Prony Representation w 4 terms'!$B$2
Name G_1: '[2]Prony Representation w 1 term'!$B$8
Name G_2: 'Prony Representation w 4 terms'!$B$3
Name G_3: 'Prony Representation w 4 terms'!$B$4
Name G_4: 'Prony Representation w 4 terms'!$B$5
Name G_5: 'Prony Representation w 4 terms'!#REF!
Name G_6: 'Prony Representation w 4 terms'!#REF!
Name G_7: 'Prony Representation w 4 terms'!#REF!
Name Sum_G: 'Prony Representation w 4 terms'!$B$7
Name T0: '[1]WLF Calculations'!$H$5
Name T0: 'WLF Calculations'!$H$5
Name Tau_1: 'Prony Representation w 4 terms'!$F$2
Name Tau_1: '[2]Prony Representation w 1 term'!$D$8
Name Tau_2: 'Prony Representation w 4 terms'!$F$3
Name Tau_3: 'Prony Representation w 4 terms'!$F$4
Name Tau_4: 'Prony Representation w 4 terms'!$F$5
Name Tau_5: 'Prony Representation w 4 terms'!#REF!
Name Tau_6: 'Prony Representation w 4 terms'!#REF!
Name Tau_7: 'Prony Representation w 4 terms'!#REF!

Sheet Original Test Data
A3: 27 0C | C3: 35 0C | E3: 45 0C | G3: 55 0C | I3: 65 0C
A4: Time | B4: Modulus | C4: Time | D4: Modulus | E4: Time | F4: Modulus | G4: Time | H4: Modulus | I4: Time | J4: Modulus
A6: (Sec) | B6: (GPa) | C6: (Sec) | D6: (GPa) | E6: (Sec) | F6: (GPa) | G6: (Sec) | H6: GPa | I6: (Sec) | J6: GPa
A7: 9 | B7: 23.95 | C7: 13 | D7: 18.89 | E7: 17 | F7: 8.81 | G7: 15 | H7: 5.67 | I7: 17 | J7: 4.92
A8: 17 | B8: 23.91 | C8: 23 | D8: 18.46 | E8: 31 | F8: 8.61 | G8: 27 | H8: 5.16 | I8: 30 | J8: 4.86
A9: 29 | B9: 23.84 | C9: 41 | D9: 18.04 | E9: 55 | F9: 8.34 | G9: 48 | H9: 5 | I9: 55 | J9: 4.76
A10: 52 | B10: 23.72 | C10: 73 | D10: 17.36 | E10: 98 | F10: 7.91 | G10: 85 | H10: 4.97 | I10: 97 | J10: 4.59
A11: 93 | B11: 23.72 | C11: 131 | D11: 16.27 | E11: 174 | F11: 7.27 | G11: 152 | H11: 4.95 | I11: 174 | J11: 4.32
A12: 166 | B12: 23.51 | C12: 233 | D12: 14.67 | E12: 310 | F12: 6.46 | G12: 271 | H12: 4.92 | I12: 309 | J12: 3.92
A13: 295 | B13: 23.16 | C13: 415 | D13: 12.63 | E13: 552 | F13: 5.67 | G13: 482 | H13: 4.86 | I13: 550 | J13: 3.41
A14: 525 | B14: 22.61 | C14: 738 | D14: 10.61 | E14: 982 | F14: 5.16 | G14: 857 | H14: 4.76 | I14: 979 | J14: 2.92
A15: 933 | B15: 21.79 | C15: 1312 | D15: 9.29 | E15: 1746 | F15: 5 | G15: 1524 | H15: 4.59 | I15: 1742 | J15: 2.6
A16: 1660 | B16: 20.73 | C16: 2334 | D16: 8.81 | E16: 3106 | F16: 4.97 | G16: 2711 | H16: 4.32 | I16: 3097 | J16: 2.5
A17: 2952 | B17: 19.66 | C17: 4151 | D17: 8.61 | E17: 5523 | F17: 4.95 | G17: 4822 | H17: 3.92 | I17: 5508 | J17: 2.5
A18: 5250 | B18: 18.89 | C18: 7381 | D18: 8.34 | E18: 9822 | F18: 4.92 | G18: 8574 | H18: 3.41 | I18: 8000 | J18: 2.5
A19: 9337 | B19: 18.46 | C19: 13126 | D19: 7.91 | E19: 17467 | F19: 4.86 | G19: 15248 | H19: 2.92 | I19: 17500 | J19: 2.5
A20: 16600 | B20: 18.04
B23: http://solidmechanics.org/text/Chapter3_6/Chapter3_6.htm
B25: http://solidmechanics.org/problems/Chapter3_6/Chapter3_6.php
B27: see Problem 3.6.5
B29: 3.6.5. The table above lists measured relaxation (shear) modulus for a (fictitious) polymer at various temperatures. The polymer has a glass transition temperature of 30 0C. 3.6.5.1. Plot a graph of the modulus as a function of time for each temperature, using a log scale for both axes 3.6.5.2. Hence, show that the data for various temperatures can be collapsed onto a single master-curve by scaling the times in each experiment by a temperature dependent factor A(T,T1), as described in Section 3.6.1. Plot the master-curve corresponding to relaxation at 27 0C. 3.6.5.3. Plot a graph of log(A(T,T1)) as a function of temperature, and show that the data can be fit by a function of the form log[A(T;T1)]=−C1(T−T1)/{C2+(T−T1)}. Determine the values of C1,C2 that best fit the data 3.6.5.4. Hence, determine the constants Cg1,Cg2 for the material, as discussed in Section 3.6.1 3.6.5.5. Hence, scale the times in the experimental data to plot the relaxation modulus at the glass transition temperature G(t,Tg). 3.6.5.6. Find a Prony series fit to G(t,Tg). Use four terms in the series, together with an appropriate value for G∞

Sheet Test Data Master Curve
A1: Shift Factors (h) -> | C1: 0 | G1: -2.606 | K1: -4.744 | O1: -6.31 | S1: -7.503
A3: 27 0C | E3: 35 0C | I3: 45 0C | M3: 55 0C | Q3: 65 0C
A4: Time | B4: Log(time) | C4: log(t)+h | D4: Modulus | E4: Time | F4: Log(time) | G4: log(t)+h | H4: Modulus | I4: Time | J4: Log(time) | K4: log(t)+h | L4: Modulus | M4: Time | N4: Log(time) | O4: log(t)+h | P4: Modulus | Q4: Time | R4: Log(time) | S4: log(t)+h | T4: Modulus
A6: (Sec) | D6: (GPa) | E6: (Sec) | H6: (GPa) | I6: (Sec) | L6: (GPa) | M6: (Sec) | P6: GPa | Q6: (Sec) | T6: GPa
A7: 9 | B7: =LOG(A7) -> 0.95424251 | C7: =B7-$C$1 -> 0.95424251 | D7: 23.95 | E7: 13 | F7: =LOG(E7) -> 1.1139434 | G7: =F7-$G$1 -> 3.7199434 | H7: 18.89 | I7: 17 | J7: =LOG(I7) -> 1.2304489 | K7: =J7-$K$1 -> 5.9744489 | L7: 8.81 | M7: 15 | N7: =LOG(M7) -> 1.1760913 | O7: =N7-$O$1 -> 7.4860913 | P7: 5.67 | Q7: 17 | R7: =LOG(Q7) -> 1.2304489 | S7: =R7-$S$1 -> 8.7334489 | T7: 4.92
A8: 17 | B8: =LOG(A8) -> 1.2304489 | C8: =B8-$C$1 -> 1.2304489 | D8: 23.91 | E8: 23 | F8: =LOG(E8) -> 1.3617278 | G8: =F8-$G$1 -> 3.9677278 | H8: 18.46 | I8: 31 | J8: =LOG(I8) -> 1.4913617 | K8: =J8-$K$1 -> 6.2353617 | L8: 8.61 | M8: 27 | N8: =LOG(M8) -> 1.4313638 | O8: =N8-$O$1 -> 7.7413638 | P8: 5.16 | Q8: 30 | R8: =LOG(Q8) -> 1.4771213 | S8: =R8-$S$1 -> 8.9801213 | T8: 4.86
A9: 29 | B9: =LOG(A9) -> 1.462398 | C9: =B9-$C$1 -> 1.462398 | D9: 23.84 | E9: 41 | F9: =LOG(E9) -> 1.6127839 | G9: =F9-$G$1 -> 4.2187839 | H9: 18.04 | I9: 55 | J9: =LOG(I9) -> 1.7403627 | K9: =J9-$K$1 -> 6.4843627 | L9: 8.34 | M9: 48 | N9: =LOG(M9) -> 1.6812412 | O9: =N9-$O$1 -> 7.9912412 | P9: 5 | Q9: 55 | R9: =LOG(Q9) -> 1.7403627 | S9: =R9-$S$1 -> 9.2433627 | T9: 4.76
A10: 52 | B10: =LOG(A10) -> 1.7160033 | C10: =B10-$C$1 -> 1.7160033 | D10: 23.72 | E10: 73 | F10: =LOG(E10) -> 1.8633229 | G10: =F10-$G$1 -> 4.4693229 | H10: 17.36 | I10: 98 | J10: =LOG(I10) -> 1.9912261 | K10: =J10-$K$1 -> 6.7352261 | L10: 7.91 | M10: 85 | N10: =LOG(M10) -> 1.9294189 | O10: =N10-$O$1 -> 8.2394189 | P10: 4.97 | Q10: 97 | R10: =LOG(Q10) -> 1.9867717 | S10: =R10-$S$1 -> 9.4897717 | T10: 4.59
A11: 93 | B11: =LOG(A11) -> 1.9684829 | C11: =B11-$C$1 -> 1.9684829 | D11: 23.72 | E11: 131 | F11: =LOG(E11) -> 2.1172713 | G11: =F11-$G$1 -> 4.7232713 | H11: 16.27 | I11: 174 | J11: =LOG(I11) -> 2.2405492 | K11: =J11-$K$1 -> 6.9845492 | L11: 7.27 | M11: 152 | N11: =LOG(M11) -> 2.1818436 | O11: =N11-$O$1 -> 8.4918436 | P11: 4.95 | Q11: 174 | R11: =LOG(Q11) -> 2.2405492 | S11: =R11-$S$1 -> 9.7435492 | T11: 4.32
A12: 166 | B12: =LOG(A12) -> 2.2201081 | C12: =B12-$C$1 -> 2.2201081 | D12: 23.51 | E12: 233 | F12: =LOG(E12) -> 2.3673559 | G12: =F12-$G$1 -> 4.9733559 | H12: 14.67 | I12: 310 | J12: =LOG(I12) -> 2.4913617 | K12: =J12-$K$1 -> 7.2353617 | L12: 6.46 | M12: 271 | N12: =LOG(M12) -> 2.4329693 | O12: =N12-$O$1 -> 8.7429693 | P12: 4.92 | Q12: 309 | R12: =LOG(Q12) -> 2.4899585 | S12: =R12-$S$1 -> 9.9929585 | T12: 3.92
A13: 295 | B13: =LOG(A13) -> 2.469822 | C13: =B13-$C$1 -> 2.469822 | D13: 23.16 | E13: 415 | F13: =LOG(E13) -> 2.6180481 | G13: =F13-$G$1 -> 5.2240481 | H13: 12.63 | I13: 552 | J13: =LOG(I13) -> 2.7419391 | K13: =J13-$K$1 -> 7.4859391 | L13: 5.67 | M13: 482 | N13: =LOG(M13) -> 2.683047 | O13: =N13-$O$1 -> 8.993047 | P13: 4.86 | Q13: 550 | R13: =LOG(Q13) -> 2.7403627 | S13: =R13-$S$1 -> 10.243363 | T13: 3.41
A14: 525 | B14: =LOG(A14) -> 2.7201593 | C14: =B14-$C$1 -> 2.7201593 | D14: 22.61 | E14: 738 | F14: =LOG(E14) -> 2.8680564 | G14: =F14-$G$1 -> 5.4740564 | H14: 10.61 | I14: 982 | J14: =LOG(I14) -> 2.9921115 | K14: =J14-$K$1 -> 7.7361115 | L14: 5.16 | M14: 857 | N14: =LOG(M14) -> 2.9329808 | O14: =N14-$O$1 -> 9.2429808 | P14: 4.76 | Q14: 979 | R14: =LOG(Q14) -> 2.9907827 | S14: =R14-$S$1 -> 10.493783 | T14: 2.92
A15: 933 | B15: =LOG(A15) -> 2.9698816 | C15: =B15-$C$1 -> 2.9698816 | D15: 21.79 | E15: 1312 | F15: =LOG(E15) -> 3.1179338 | G15: =F15-$G$1 -> 5.7239338 | H15: 9.29 | I15: 1746 | J15: =LOG(I15) -> 3.2420442 | K15: =J15-$K$1 -> 7.9860442 | L15: 5 | M15: 1524 | N15: =LOG(M15) -> 3.182985 | O15: =N15-$O$1 -> 9.492985 | P15: 4.59 | Q15: 1742 | R15: =LOG(Q15) -> 3.2410482 | S15: =R15-$S$1 -> 10.744048 | T15: 2.6
A16: 1660 | B16: =LOG(A16) -> 3.2201081 | C16: =B16-$C$1 -> 3.2201081 | D16: 20.73 | E16: 2334 | F16: =LOG(E16) -> 3.3681009 | G16: =F16-$G$1 -> 5.9741009 | H16: 8.81 | I16: 3106 | J16: =LOG(I16) -> 3.4922015 | K16: =J16-$K$1 -> 8.2362015 | L16: 4.97 | M16: 2711 | N16: =LOG(M16) -> 3.4331295 | O16: =N16-$O$1 -> 9.7431295 | P16: 4.32 | Q16: 3097 | R16: =LOG(Q16) -> 3.4909412 | S16: =R16-$S$1 -> 10.993941 | T16: 2.5
A17: 2952 | B17: =LOG(A17) -> 3.4701164 | C17: =B17-$C$1 -> 3.4701164 | D17: 19.66 | E17: 4151 | F17: =LOG(E17) -> 3.6181527 | G17: =F17-$G$1 -> 6.2241527 | H17: 8.61 | I17: 5523 | J17: =LOG(I17) -> 3.742175 | K17: =J17-$K$1 -> 8.486175 | L17: 4.95 | M17: 4822 | N17: =LOG(M17) -> 3.6832272 | O17: =N17-$O$1 -> 9.9932272 | P17: 3.92 | Q17: 5508 | R17: =LOG(Q17) -> 3.7409939 | S17: =R17-$S$1 -> 11.243994 | T17: 2.5
A18: 5250 | B18: =LOG(A18) -> 3.7201593 | C18: =B18-$C$1 -> 3.7201593 | D18: 18.89 | E18: 7381 | F18: =LOG(E18) -> 3.8681152 | G18: =F18-$G$1 -> 6.4741152 | H18: 8.34 | I18: 9822 | J18: =LOG(I18) -> 3.9921999 | K18: =J18-$K$1 -> 8.7361999 | L18: 4.92 | M18: 8574 | N18: =LOG(M18) -> 3.9331835 | O18: =N18-$O$1 -> 10.243183 | P18: 3.41 | Q18: 8000 | R18: =LOG(Q18) -> 3.90309 | S18: =R18-$S$1 -> 11.40609 | T18: 2.5
A19: 9337 | B19: =LOG(A19) -> 3.9702074 | C19: =B19-$C$1 -> 3.9702074 | D19: 18.46 | E19: 13126 | F19: =LOG(E19) -> 4.1181324 | G19: =F19-$G$1 -> 6.7241324 | H19: 7.91 | I19: 17467 | J19: =LOG(I19) -> 4.2422183 | K19: =J19-$K$1 -> 8.9862183 | L19: 4.86 | M19: 15248 | N19: =LOG(M19) -> 4.1832129 | O19: =N19-$O$1 -> 10.493213 | P19: 2.92 | Q19: 17500 | R19: =LOG(Q19) -> 4.243038 | S19: =R19-$S$1 -> 11.746038 | T19: 2.5
A20: 16600 | B20: =LOG(A20) -> 4.2201081 | C20: =B20-$C$1 -> 4.2201081 | D20: 18.04

Sheet WLF Calculations
B1: Test | C1: WLF | D1: Relative
B2: Shift | C2: Shift | D2: SQUARE
A3: Temp. | B3: Factors | C3: Factors | D3: ERROR | G3: C1= | H3: 14.937543
A4: 27 | B4: ='Test Data Master Curve'!C1 -> 0 | C4: =-_C1*(A4-T0)/(_C2+(A4-T0)) -> 0 | D4: 0 | G4: C2= | H4: 38.13064
A5: 35 | B5: ='Test Data Master Curve'!G1 -> -2.606 | C5: =-_C1*(A5-T0)/(_C2+(A5-T0)) -> -2.5904766 | D5: =(1-C5/B5)^2 -> 3.5483238e-05 | G5: T0= | H5: 27
A6: 45 | B6: ='Test Data Master Curve'!K1 -> -4.744 | C6: =-_C1*(A6-T0)/(_C2+(A6-T0)) -> -4.7901783 | D6: =(1-C6/B6)^2 -> 9.4751773e-05
A7: 55 | B7: ='Test Data Master Curve'!O1 -> -6.31 | C7: =-_C1*(A7-T0)/(_C2+(A7-T0)) -> -6.3246206 | D7: =(1-C7/B7)^2 -> 5.3687278e-06
A8: 65 | B8: ='Test Data Master Curve'!S1 -> -7.503 | C8: =-_C1*(A8-T0)/(_C2+(A8-T0)) -> -7.4559552 | D8: =(1-C8/B8)^2 -> 3.9314593e-05
D9: =SUM(D5:D8) -> 0.00017491833 | E9: Error Sum
N12: temp | O12: WLF
N13: 10 | O13: =-_C1*(N13-T0)/(_C2+(N13-T0)) -> 12.017536
N14: 15 | O14: =-_C1*(N14-T0)/(_C2+(N14-T0)) -> 6.8597829
N15: 20 | O15: =-_C1*(N15-T0)/(_C2+(N15-T0)) -> 3.3588388
N16: 30 | O16: =-_C1*(N16-T0)/(_C2+(N16-T0)) -> -1.0895194
N17: 40 | O17: =-_C1*(N17-T0)/(_C2+(N17-T0)) -> -3.7978805
N18: 50 | O18: =-_C1*(N18-T0)/(_C2+(N18-T0)) -> -5.6201521
N19: 60 | O19: =-_C1*(N19-T0)/(_C2+(N19-T0)) -> -6.9300504
N20: 70 | O20: =-_C1*(N20-T0)/(_C2+(N20-T0)) -> -7.9170379
N21: 80 | O21: =-_C1*(N21-T0)/(_C2+(N21-T0)) -> -8.6874161
N22: 80 | O22: =-_C1*(N22-T0)/(_C2+(N22-T0)) -> -8.6874161
N23: 100 | O23: =-_C1*(N23-T0)/(_C2+(N23-T0)) -> -9.8122413
N24: 110 | O24: =-_C1*(N24-T0)/(_C2+(N24-T0)) -> -10.235363

Sheet Prony Setup
L2: Master Curve Data
L4: Normalized | N4: Shear
A5: 27 0C | L5: Shear | M5: Time | N5: Modulus
A6: time | B6: modulus | L6: Modulus | M6: (secs) | N6: Gpa
A7: =10^('Test Data Master Curve'!C7) -> 9 | B7: ='Test Data Master Curve'!D7 -> 23.95 | L7: =N7/$N$7 -> 1 | M7: =A7 -> 9 | N7: =B7 -> 23.95
A8: =10^('Test Data Master Curve'!C8) -> 17 | B8: ='Test Data Master Curve'!D8 -> 23.91 | L8: =N8/$N$7 -> 0.99832985 | M8: =A8 -> 17 | N8: =B8 -> 23.91
A9: =10^('Test Data Master Curve'!C9) -> 29 | B9: ='Test Data Master Curve'!D9 -> 23.84 | L9: =N9/$N$7 -> 0.9954071 | M9: =A9 -> 29 | N9: =B9 -> 23.84
A10: =10^('Test Data Master Curve'!C10) -> 52 | B10: ='Test Data Master Curve'!D10 -> 23.72 | L10: =N10/$N$7 -> 0.99039666 | M10: =A10 -> 52 | N10: =B10 -> 23.72
A11: =10^('Test Data Master Curve'!C11) -> 93 | B11: ='Test Data Master Curve'!D11 -> 23.72 | L11: =N11/$N$7 -> 0.99039666 | M11: =A11 -> 93 | N11: =B11 -> 23.72
A12: =10^('Test Data Master Curve'!C12) -> 166 | B12: ='Test Data Master Curve'!D12 -> 23.51 | L12: =N12/$N$7 -> 0.98162839 | M12: =A12 -> 166 | N12: =B12 -> 23.51
A13: =10^('Test Data Master Curve'!C13) -> 295 | B13: ='Test Data Master Curve'!D13 -> 23.16 | L13: =N13/$N$7 -> 0.96701461 | M13: =A13 -> 295 | N13: =B13 -> 23.16
A14: =10^('Test Data Master Curve'!C14) -> 525 | B14: ='Test Data Master Curve'!D14 -> 22.61 | L14: =N14/$N$7 -> 0.9440501 | M14: =A14 -> 525 | N14: =B14 -> 22.61
A15: =10^('Test Data Master Curve'!C15) -> 933 | B15: ='Test Data Master Curve'!D15 -> 21.79 | L15: =N15/$N$7 -> 0.90981211 | M15: =A15 -> 933 | N15: =B15 -> 21.79
A16: =10^('Test Data Master Curve'!C16) -> 1660 | B16: ='Test Data Master Curve'!D16 -> 20.73 | C16: 35 0C | L16: =N16/$N$7 -> 0.86555324 | M16: =A16 -> 1660 | N16: =B16 -> 20.73
A17: =10^('Test Data Master Curve'!C17) -> 2952 | B17: ='Test Data Master Curve'!D17 -> 19.66 | C17: time | D17: modulus | L17: =N17/$N$7 -> 0.82087683 | M17: =A17 -> 2952 | N17: =B17 -> 19.66
C18: =10^('Test Data Master Curve'!G7) -> 5247.3901 | D18: ='Test Data Master Curve'!H7 -> 18.89 | L18: =N18/$N$7 -> 0.78872651 | M18: =C18 -> 5247.3901 | N18: =D18 -> 18.89
A19: =10^('Test Data Master Curve'!C18) -> 5250 | B19: ='Test Data Master Curve'!D18 -> 18.89 | L19: =N19/$N$7 -> 0.78872651 | M19: =A19 -> 5250 | N19: =B19 -> 18.89
C20: =10^('Test Data Master Curve'!G8) -> 9283.844 | D20: ='Test Data Master Curve'!H8 -> 18.46 | L20: =N20/$N$7 -> 0.77077244 | M20: =C20 -> 9283.844 | N20: =D20 -> 18.46
A21: =10^('Test Data Master Curve'!C19) -> 9337 | B21: ='Test Data Master Curve'!D19 -> 18.46 | L21: =N21/$N$7 -> 0.77077244 | M21: =A21 -> 9337 | N21: =B21 -> 18.46
C22: =10^('Test Data Master Curve'!G9) -> 16549.461 | D22: ='Test Data Master Curve'!H9 -> 18.04 | L22: =N22/$N$7 -> 0.75323591 | M22: =C22 -> 16549.461 | N22: =D22 -> 18.04
A23: =10^('Test Data Master Curve'!C20) -> 16600 | B23: ='Test Data Master Curve'!D20 -> 18.04 | L23: =N23/$N$7 -> 0.75323591 | M23: =A23 -> 16600 | N23: =B23 -> 18.04
C24: =10^('Test Data Master Curve'!G10) -> 29466.114 | D24: ='Test Data Master Curve'!H10 -> 17.36 | L24: =N24/$N$7 -> 0.72484342 | M24: =C24 -> 29466.114 | N24: =D24 -> 17.36
C25: =10^('Test Data Master Curve'!G11) -> 52877.546 | D25: ='Test Data Master Curve'!H11 -> 16.27 | L25: =N25/$N$7 -> 0.67933194 | M25: =C25 -> 52877.546 | N25: =D25 -> 16.27
C26: =10^('Test Data Master Curve'!G12) -> 94049.377 | D26: ='Test Data Master Curve'!H12 -> 14.67 | L26: =N26/$N$7 -> 0.6125261 | M26: =C26 -> 94049.377 | N26: =D26 -> 14.67
C27: =10^('Test Data Master Curve'!G13) -> 167512.84 | D27: ='Test Data Master Curve'!H13 -> 12.63 | L27: =N27/$N$7 -> 0.52734864 | M27: =C27 -> 167512.84 | N27: =D27 -> 12.63
C28: =10^('Test Data Master Curve'!G14) -> 297890.3 | D28: ='Test Data Master Curve'!H14 -> 10.61 | L28: =N28/$N$7 -> 0.44300626 | M28: =C28 -> 297890.3 | N28: =D28 -> 10.61
C29: =10^('Test Data Master Curve'!G15) -> 529582.76 | D29: ='Test Data Master Curve'!H15 -> 9.29 | E29: 45 0C | L29: =N29/$N$7 -> 0.38789144 | M29: =C29 -> 529582.76 | N29: =D29 -> 9.29
C30: =10^('Test Data Master Curve'!G16) -> 942108.35 | D30: ='Test Data Master Curve'!H16 -> 8.81 | E30: time | F30: modulus | L30: =N30/$N$7 -> 0.36784969 | M30: =C30 -> 942108.35 | N30: =D30 -> 8.81
E31: =10^('Test Data Master Curve'!K7) -> 942863.71 | F31: ='Test Data Master Curve'!L7 -> 8.81 | L31: =N31/$N$7 -> 0.36784969 | M31: =E31 -> 942863.71 | N31: =F31 -> 8.81
C32: =10^('Test Data Master Curve'!G17) -> 1675532 | D32: ='Test Data Master Curve'!H17 -> 8.61 | L32: =N32/$N$7 -> 0.35949896 | M32: =C32 -> 1675532 | N32: =D32 -> 8.61
E33: =10^('Test Data Master Curve'!K8) -> 1719339.7 | F33: ='Test Data Master Curve'!L8 -> 8.61 | L33: =N33/$N$7 -> 0.35949896 | M33: =E33 -> 1719339.7 | N33: =F33 -> 8.61
C34: =10^('Test Data Master Curve'!G18) -> 2979306.6 | D34: ='Test Data Master Curve'!H18 -> 8.34 | L34: =N34/$N$7 -> 0.34822547 | M34: =C34 -> 2979306.6 | N34: =D34 -> 8.34
E35: =10^('Test Data Master Curve'!K9) -> 3050441.4 | F35: ='Test Data Master Curve'!L9 -> 8.34 | L35: =N35/$N$7 -> 0.34822547 | M35: =E35 -> 3050441.4 | N35: =F35 -> 8.34
C36: =10^('Test Data Master Curve'!G19) -> 5298249.4 | D36: ='Test Data Master Curve'!H19 -> 7.91 | L36: =N36/$N$7 -> 0.3302714 | M36: =C36 -> 5298249.4 | N36: =D36 -> 7.91
E37: =10^('Test Data Master Curve'!K10) -> 5435332 | F37: ='Test Data Master Curve'!L10 -> 7.91 | L37: =N37/$N$7 -> 0.3302714 | M37: =E37 -> 5435332 | N37: =F37 -> 7.91
E38: =10^('Test Data Master Curve'!K11) -> 9650487.4 | F38: ='Test Data Master Curve'!L11 -> 7.27 | L38: =N38/$N$7 -> 0.30354906 | M38: =E38 -> 9650487.4 | N38: =F38 -> 7.27
E39: =10^('Test Data Master Curve'!K12) -> 17193397 | F39: ='Test Data Master Curve'!L12 -> 6.46 | G39: 55 0C | L39: =N39/$N$7 -> 0.2697286 | M39: =E39 -> 17193397 | N39: =F39 -> 6.46
E40: =10^('Test Data Master Curve'!K13) -> 30615339 | F40: ='Test Data Master Curve'!L13 -> 5.67 | G40: time | H40: modulus | L40: =N40/$N$7 -> 0.23674322 | M40: =E40 -> 30615339 | N40: =F40 -> 5.67
G41: =10^('Test Data Master Curve'!O7) -> 30626069 | H41: ='Test Data Master Curve'!P7 -> 5.67 | L41: =N41/$N$7 -> 0.23674322 | M41: =G41 -> 30626069 | N41: =H41 -> 5.67
E42: =10^('Test Data Master Curve'!K14) -> 54464245 | F42: ='Test Data Master Curve'!L14 -> 5.16 | L42: =N42/$N$7 -> 0.21544885 | M42: =E42 -> 54464245 | N42: =F42 -> 5.16
...

Sheet Prony Representation w 4 terms
A2: g_1 | B2: 0.20763 | E2: Tau_1 | F2: 1694
A3: g_2 | B3: 0.41734 | E3: Tau_2 | F3: 168038
A4: g_3 | B4: 0.16637 | E4: Tau_3 | F4: 17225100
A5: g_4 | B5: 0.10436 | E5: Tau_4 | F5: 17440800000
A7: Sum of g's | B7: =SUM(B2:B5) -> 0.8957
B9: time | D9: Term 1 | E9: Term 2 | F9: Term 3 | G9: Term 4 | I9: 1-Sum
B10: 1 | D10: =G_1*(1-EXP(-B10/Tau_1)) -> 0.00012253172 | E10: =G_2*(1-EXP(-B10/Tau_2)) -> 2.4835975e-06 | F10: =G_3*(1-EXP(-B10/Tau_3)) -> 9.6585793e-09 | G10: =G_4*(1-EXP(-B10/Tau_4)) -> 5.9836687e-12 | I10: =1-SUM(D10:G10) -> 0.99987498
B11: 2 | D11: =G_1*(1-EXP(-B11/Tau_1)) -> 0.00024499112 | E11: =G_2*(1-EXP(-B11/Tau_2)) -> 4.9671802e-06 | F11: =G_3*(1-EXP(-B11/Tau_3)) -> 1.9317158e-08 | G11: =G_4*(1-EXP(-B11/Tau_4)) -> 1.1967337e-11 | I11: =1-SUM(D11:G11) -> 0.99975002
B12: 3 | D12: =G_1*(1-EXP(-B12/Tau_1)) -> 0.00036737826 | E12: =G_2*(1-EXP(-B12/Tau_2)) -> 7.4507482e-06 | F12: =G_3*(1-EXP(-B12/Tau_3)) -> 2.8975736e-08 | G12: =G_4*(1-EXP(-B12/Tau_4)) -> 1.7951006e-11 | I12: =1-SUM(D12:G12) -> 0.99962514
B13: 10 | D13: =G_1*(1-EXP(-B13/Tau_1)) -> 0.0012220683 | E13: =G_2*(1-EXP(-B13/Tau_2)) -> 2.483531e-05 | F13: =G_3*(1-EXP(-B13/Tau_3)) -> 9.6585768e-08 | G13: =G_4*(1-EXP(-B13/Tau_4)) -> 5.983671e-11 | I13: =1-SUM(D13:G13) -> 0.998753
B14: 20 | D14: =G_1*(1-EXP(-B14/Tau_1)) -> 0.0024369437 | E14: =G_2*(1-EXP(-B14/Tau_2)) -> 4.9669142e-05 | F14: =G_3*(1-EXP(-B14/Tau_3)) -> 1.9317148e-07 | G14: =G_4*(1-EXP(-B14/Tau_4)) -> 1.1967341e-10 | I14: =1-SUM(D14:G14) -> 0.99751319
B15: 30 | D15: =G_1*(1-EXP(-B15/Tau_1)) -> 0.0036446686 | E15: =G_2*(1-EXP(-B15/Tau_2)) -> 7.4501496e-05 | F15: =G_3*(1-EXP(-B15/Tau_3)) -> 2.8975714e-07 | G15: =G_4*(1-EXP(-B15/Tau_4)) -> 1.7951012e-10 | I15: =1-SUM(D15:G15) -> 0.99628054
B16: 100 | D16: =G_1*(1-EXP(-B16/Tau_1)) -> 0.011902033 | E16: =G_2*(1-EXP(-B16/Tau_2)) -> 0.0002482866 | F16: =G_3*(1-EXP(-B16/Tau_3)) -> 9.6585516e-07 | G16: =G_4*(1-EXP(-B16/Tau_4)) -> 5.9836705e-10 | I16: =1-SUM(D16:G16) -> 0.98784871
B17: 200 | D17: =G_1*(1-EXP(-B17/Tau_1)) -> 0.023121802 | E17: =G_2*(1-EXP(-B17/Tau_2)) -> 0.0004964255 | F17: =G_3*(1-EXP(-B17/Tau_3)) -> 1.9317047e-06 | G17: =G_4*(1-EXP(-B17/Tau_4)) -> 1.1967341e-09 | I17: =1-SUM(D17:G17) -> 0.97637984
B18: 300 | D18: =G_1*(1-EXP(-B18/Tau_1)) -> 0.033698417 | E18: =G_2*(1-EXP(-B18/Tau_2)) -> 0.00074441676 | F18: =G_3*(1-EXP(-B18/Tau_3)) -> 2.8975487e-06 | G18: =G_4*(1-EXP(-B18/Tau_4)) -> 1.7951011e-09 | I18: =1-SUM(D18:G18) -> 0.96555427
B19: 1000 | D19: =G_1*(1-EXP(-B19/Tau_1)) -> 0.092571709 | E19: =G_2*(1-EXP(-B19/Tau_2)) -> 0.0024762295 | F19: =G_3*(1-EXP(-B19/Tau_3)) -> 9.6582993e-06 | G19: =G_4*(1-EXP(-B19/Tau_4)) -> 5.9836703e-09 | I19: =1-SUM(D19:G19) -> 0.9049424
B20: 2000 | D20: =G_1*(1-EXP(-B20/Tau_1)) -> 0.14387038 | E20: =G_2*(1-EXP(-B20/Tau_2)) -> 0.0049377667 | F20: =G_3*(1-EXP(-B20/Tau_3)) -> 1.9316038e-05 | G20: =G_4*(1-EXP(-B20/Tau_4)) -> 1.196734e-08 | I20: =1-SUM(D20:G20) -> 0.85117253
B21: 3000 | D21: =G_1*(1-EXP(-B21/Tau_1)) -> 0.17229757 | E21: =G_2*(1-EXP(-B21/Tau_2)) -> 0.0073846987 | F21: =G_3*(1-EXP(-B21/Tau_3)) -> 2.8973216e-05 | G21: =G_4*(1-EXP(-B21/Tau_4)) -> 1.795101e-08 | I21: =1-SUM(D21:G21) -> 0.82028874
... B49: 10000000000000 | D49: =G_1*(1-EXP(-B49/Tau_1)) -> 0.20763 | E49: =G_2*(1-EXP(-B49/Tau_2)) -> 0.41734 | F49: =G_3*(1-EXP(-B49/Tau_3)) -> 0.16637 | G49: =G_4*(1-EXP(-B49/Tau_4)) -> 0.10436 | I49: =1-SUM(D49:G49) -> 0.1043
C53: Note: From Abaqus with default errtol = 0.01
C54: I | D54: G(I) | E54: K(I) | F54: TAU(I)
C56: 1 | D56: 0.20763 | E56: 0 | F56: 1694
C57: 2 | D57: 0.41734 | E57: 0 | F57: 168038
C58: 3 | D58: 0.16637 | E58: 0 | F58: 17225100
C59: 4 | D59: 0.10436 | E59: 0 | F59: 17440800000
C62: Sum of g's | D62: =SUM(D56:D60) -> 0.8957

Sheet Sim_27
A2: 27 0C | S2: *Heading
B3: Shear | S3: Template file for running Parametric Study
A4: Time | B4: Relaxation | S4: Run Parametric Study using commnad "abaqus script=Bower_TRS_Example.psf"
B5: Modulus | S5: Unit Cube in Simple Shear, Stress Relaxation
A6: (secs) | B6: (GPa) | S6: Loading:
A7: 1 | B7: 23.948503 | S7: Step 1: Impose linear ramp of strain in 1 second.
A8: 2 | B8: 23.945509 | S8: Step 2: Hold strain constant for 30,000 secs.
A9: 3 | B9: 23.942517 | S9: Linear Viscoelastic + TRS material model
A10: 4 | B10: 23.939528 | S10: **
A11: 6 | B11: 23.933552 | S11: *Parameter
A12: 11 | B12: 23.918645 | S12: temperature = 27.0
A13: 21 | B13: 23.88896 | S13: max_strain = 0.01
A14: 31 | B14: 23.859447 | S14: **
A15: 51 | B15: 23.80093 | S15: *Material, Name=mat
A16: 101 | B16: 23.657563 | S16: **
A17: 201 | B17: 23.382963 | S17: ** Units: [length]=meter, [force] = Newton, [time] = seconds, [temperature] = Celsius
A18: 301 | B18: 23.123765 | S18: ** [stress]=GPa
... A26: 30001 | B26: 17.33605 | S26: ** g_i, kappa_i, tau_i
S27: 0.20763, 0.0, 1694.
S28: 0.41734, 0.0, 168038.
C29: *Material, name=mat | S29: 0.16637, 0.0, 17225100.
C30: ** | S30: 0.10436, 0.0, 17440800000.
C31: ** Units: [length]=meter, [force] = Newton, [time] = seconds, [temperature] = Celsius | S31: *TRS, Definition=WLF
C32: ** [stress] =GPa | S32: 27, 14.94, 38.13
C33: ** Reference Temperature for TRS is 27 degrees C | S33: **
C34: ** | S34: ** PARTS
C35: *Hyperelastic, neohooke, moduli=instant | S35: **
C36: 11.975, 0.0 | S36: *Part, Name=UnitCube
C37: *Viscoelastic, time=prony | S37: *Node, Nset=all
C38: ** g_i, kappa_i, tau_i | S38: 1, 0, 0, 0
C39: 0.20763, 0.0, 1694 | S39: 2, 0, 0, 1
C40: 0.41734, 0.0, 168000 | S40: 3, 1, 0, 1
... C44: 27, 14.94, 38.13 | S44: 7, 1, 1, 1
S45: 8, 1, 1, 0
S46: *Nset, Nset=nLeft
S47: 1, 2, 5, 6
S48: *Nset, Nset=nBot
S49: 1, 2, 3, 4
S50: *Nset, Nset=nBack
S51: 1, 4, 5, 8
...

Sheet Sim_35
A2: 35 0C
B3: Shear
A4: Time | B4: Relaxation
B5: Modulus
A6: (secs) | B6: (GPa)
A7: 1 | B7: 23.407604
A8: 2 | B8: 22.471143
A9: 3 | B9: 21.72249
A10: 4 | B10: 21.123041
A11: 6 | B11: 20.255409
A12: 11 | B12: 19.180395
A13: 21 | B13: 18.555629
A14: 31 | B14: 18.296078
A15: 51 | B15: 17.867599
A16: 101 | B16: 16.889268
A17: 201 | B17: 15.241016
A18: 301 | B18: 13.93223
... A26: 30001 | B26: 7.0162848

Sheet Sim_45
A2: 45 0C
B3: Shear
A4: Time | B4: Relaxation
B5: Modulus
A6: (secs) | B6: (GPa)
A7: 1 | B7: 17.474356
A8: 2 | B8: 14.750056
A9: 3 | B9: 12.954165
A10: 4 | B10: 11.706631
A11: 6 | B11: 10.233607
A12: 11 | B12: 9.0459183
A13: 21 | B13: 8.7045655
A14: 31 | B14: 8.568795
A15: 51 | B15: 8.3211668
A16: 101 | B16: 7.7747867
A17: 201 | B17: 6.9362812
A18: 301 | B18: 6.3503101
... A26: 30001 | B26: 4.7453251

Sheet Sim_55
A2: 55 0C
B3: Shear
A4: Time | B4: Relaxation
B5: Modulus
A6: (secs) | B6: (GPa)
A7: 1 | B7: 9.5440663
A8: 2 | B8: 8.3127692
A9: 3 | B9: 7.9289891
A10: 4 | B10: 7.5895607
A11: 6 | B11: 7.0238277
A12: 11 | B12: 6.0912263
A13: 21 | B13: 5.3121544
A14: 31 | B14: 5.0820764
A15: 51 | B15: 4.9901713
A16: 101 | B16: 4.9671192
A17: 201 | B17: 4.9373124
A18: 301 | B18: 4.9078822
... A26: 30001 | B26: 2.5635002

Sheet Sim_65
A2: 65 0C
B3: Shear
A4: Time | B4: Relaxation
B5: Modulus
A6: (secs) | B6: (GPa)
A7: 1 | B7: 6.9955468
A8: 2 | B8: 5.3589955
A9: 3 | B9: 5.0568227
A10: 4 | B10: 4.9962703
A11: 6 | B11: 4.9753945
A12: 11 | B12: 4.9546544
A13: 21 | B13: 4.9146175
A14: 31 | B14: 4.875233
A15: 51 | B15: 4.7983792
A16: 101 | B16: 4.6169396
A17: 201 | B17: 4.295864
A18: 301 | B18: 4.0234394
... A26: 30001 | B26: 2.497985

Sheet PSF File
B2: from odbAccess import openOdb
B3: import win32com.client
B4: from textRepr import prettyPrint as pp
B6: #~~~~~~~~~~~~~~~~~~~~~~~~~~~~~~~~~~~~~~~~~~~~~~~~~~~~~~~~~~~~~~~~~~~~~~~~~
B7: # Automates the running of 5 different stress relaxation tests
B8: # Each Stress Relaxation test loads the specimen at different temperatures
B9: # Temperatures are: 27, 35, 45, 55, 65 C
B10: #
B11: # The script computes the shear modulus=shear strain, S12, divided by
B12: # the shear strain (0.01).
B13: #
B14: # The script saves the(Time, Shear Modulus) data back to an Excel sheet.
... B111: print
