Workbook
Name _C10: Plots!$E$36
Name _C20: Plots!$E$37
Name _C30: Plots!$E$38
Name alpha: ST_S58!$B$36
Name beta: ST_S58!$B$37
Name EB_S58: 'just data'!$D$5:$D$54
Name EB_S58_1: EB_S58!$A$7:$A$56
Name gamma: ST_S58!$B$38
Name PT_S58: 'just data'!$H$5:$I$42
Name Yeoh_from_Abaqus: 'from Abaqus'!$A$3:$K$171

Sheet Plots
A1: Yeoh Material Model Calibration of an Elastomer, using Simple Tension, Equi-Biaxial Tension, and Planar Tension test data
D31: Uniaxial Total SSError= | E31: =ST_S58!H51 -> 0.39929441 | O31: Equi-Biaxial Total SSError = | P31: =EB_S58!H58 -> 0.33605535 | X31: Planar Tension Total SSError = | Y31: =PT_S58!H46 -> 0.11892217 | AB31: Total SSE= | AC31: =SUM(E31,P31,Y31) -> 0.85427193
D33: Uniaxial AD Error = | E33: =ST_S58!S51 -> 0.90341149 | O33: Equi-Biaxial AD Error = | P33: =EB_S58!S58 -> 0.82477087 | X33: Planar Tension AD Error = | Y33: =PT_S58!S46 -> 0.38208629 | AB33: Total AD Err = | AC33: =SUM(E33,P33,Y33) -> 2.1102687
D36: C10= | E36: =K36/100 -> 0.18 | K36: 18 | N36: If C20 and C30 are set to zero, then this becomes the Neo-Hookean model
D37: C20= | E37: =-0.04+0.08/100*K37 -> -0.0094620974 | K37: 38.172378 | N37: This paper by Dr. Yeoh is a good reference for a variety of hyperelastic models:
D38: C30= | E38: =0.05*K38/100 -> 0.002 | K38: 4 | N38: Yeoh, O. H., “Some Forms of the Strain Energy Function for Rubber,” Rubber Chemistry and Technology, vol. 66, pp. 754–771, 1993.

Sheet ST_S58
D1: Yeoh Calibration of an Elastomer, Simple Tension test data
A3: UNIAXIAL
A4: TEST DATA | H4: Relative | L4: C10= | M4: =_C10 -> 0.18 | Q4: Absolute | S4: Absolute
A5: Eng. | B5: Eng. | E5: Uniaxial | F5: Uniaxial | H5: SQUARE | Q5: SQUARE | S5: value
A6: Strain | B6: Stress | D6: Stretch | E6: Invariant | F6: Calc Stress | H6: ERROR | Q6: ERROR | S6: ERROR
A7: 0 | B7: 0 | D7: =A7+1 -> 1 | E7: =D7^2+2/D7 -> 3 | F7: =2*(D7-1/D7^2)*(_C10+2*_C20*(E7-3)+3*_C30*(E7-3)^2) -> 0
A8: 0.0186 | B8: 0.0281 | D8: =A8+1 -> 1.0186 | E8: =D8^2+2/D8 -> 3.0010252 | F8: =2*(D8-1/D8^2)*(_C10+2*_C20*(E8-3)+3*_C30*(E8-3)^2) -> 0.019721293 | H8: =(1-F8/B8)^2 -> 0.088908099 | Q8: =(F8-B8)^2 -> 7.0202724e-05 | S8: =ABS(F8-B8) -> 0.0083787066
A9: 0.0372 | B9: 0.0515 | D9: =A9+1 -> 1.0372 | E9: =D9^2+2/D9 -> 3.0040523 | F9: =2*(D9-1/D9^2)*(_C10+2*_C20*(E9-3)+3*_C30*(E9-3)^2) -> 0.038735794 | H9: =(1-F9/B9)^2 -> 0.061428955 | Q9: =(F9-B9)^2 -> 0.00016292495 | S9: =ABS(F9-B9) -> 0.012764206
A10: 0.0575 | B10: 0.0716 | D10: =A10+1 -> 1.0575 | E10: =D10^2+2/D10 -> 3.0095592 | F10: =2*(D10-1/D10^2)*(_C10+2*_C20*(E10-3)+3*_C30*(E10-3)^2) -> 0.058725704 | H10: =(1-F10/B10)^2 -> 0.032331135 | Q10: =(F10-B10)^2 -> 0.0001657475 | S10: =ABS(F10-B10) -> 0.012874296
A11: 0.0777 | B11: 0.0906 | D11: =A11+1 -> 1.0777 | E11: =D11^2+2/D11 -> 3.0172413 | F11: =2*(D11-1/D11^2)*(_C10+2*_C20*(E11-3)+3*_C30*(E11-3)^2) -> 0.077870593 | H11: =(1-F11/B11)^2 -> 0.019740583 | Q11: =(F11-B11)^2 -> 0.00016203781 | S11: =ABS(F11-B11) -> 0.012729407
A12: 0.0974 | B12: 0.1085 | D12: =A12+1 -> 1.0974 | E12: =D12^2+2/D12 -> 3.0267763 | F12: =2*(D12-1/D12^2)*(_C10+2*_C20*(E12-3)+3*_C30*(E12-3)^2) -> 0.095863551 | H12: =(1-F12/B12)^2 -> 0.013564089 | Q12: =(F12-B12)^2 -> 0.00015967984 | S12: =ABS(F12-B12) -> 0.012636449
A13: 0.1172 | B13: 0.1254 | D13: =A13+1 -> 1.1172 | E13: =D13^2+2/D13 -> 3.0383256 | F13: =2*(D13-1/D13^2)*(_C10+2*_C20*(E13-3)+3*_C30*(E13-3)^2) -> 0.11330904 | H13: =(1-F13/B13)^2 -> 0.009296649 | Q13: =(F13-B13)^2 -> 0.00014619129 | S13: =ABS(F13-B13) -> 0.012090959
A14: 0.1374 | B14: 0.1414 | D14: =A14+1 -> 1.1374 | E14: =D14^2+2/D14 -> 3.0520751 | F14: =2*(D14-1/D14^2)*(_C10+2*_C20*(E14-3)+3*_C30*(E14-3)^2) -> 0.13048143 | H14: =(1-F14/B14)^2 -> 0.0059625619 | Q14: =(F14-B14)^2 -> 0.00011921522 | S14: =ABS(F14-B14) -> 0.010918572
A15: 0.1581 | B15: 0.1566 | D15: =A15+1 -> 1.1581 | E15: =D15^2+2/D15 -> 3.0681622 | F15: =2*(D15-1/D15^2)*(_C10+2*_C20*(E15-3)+3*_C30*(E15-3)^2) -> 0.1474576 | H15: =(1-F15/B15)^2 -> 0.0034082893 | Q15: =(F15-B15)^2 -> 8.3583387e-05 | S15: =ABS(F15-B15) -> 0.009142395
A16: 0.1778 | B16: 0.1718 | D16: =A16+1 -> 1.1778 | E16: =D16^2+2/D16 -> 3.085294 | F16: =2*(D16-1/D16^2)*(_C10+2*_C20*(E16-3)+3*_C30*(E16-3)^2) -> 0.16305964 | H16: =(1-F16/B16)^2 -> 0.0025882857 | Q16: =(F16-B16)^2 -> 7.6393873e-05 | S16: =ABS(F16-B16) -> 0.0087403589
A17: 0.1991 | B17: 0.1848 | D17: =A17+1 -> 1.1991 | E17: =D17^2+2/D17 -> 3.1057584 | F17: =2*(D17-1/D17^2)*(_C10+2*_C20*(E17-3)+3*_C30*(E17-3)^2) -> 0.17935232 | H17: =(1-F17/B17)^2 -> 0.00086899961 | Q17: =(F17-B17)^2 -> 2.9677241e-05 | S17: =ABS(F17-B17) -> 0.0054476821
A18: 0.2202 | B18: 0.1985 | D18: =A18+1 -> 1.2202 | E18: =D18^2+2/D18 -> 3.1279636 | F18: =2*(D18-1/D18^2)*(_C10+2*_C20*(E18-3)+3*_C30*(E18-3)^2) -> 0.19493182 | H18: =(1-F18/B18)^2 -> 0.00032312594 | Q18: =(F18-B18)^2 -> 1.2731889e-05 | S18: =ABS(F18-B18) -> 0.0035681773
A19: 0.2408 | B19: 0.211 | D19: =A19+1 -> 1.2408 | E19: =D19^2+2/D19 -> 3.151448 | F19: =2*(D19-1/D19^2)*(_C10+2*_C20*(E19-3)+3*_C30*(E19-3)^2) -> 0.20963222 | H19: =(1-F19/B19)^2 -> 4.2021089e-05 | Q19: =(F19-B19)^2 -> 1.8708209e-06 | S19: =ABS(F19-B19) -> 0.0013677795
... A36: 0.5996 | B36: 0.3746 | D36: =A36+1 -> 1.5996 | E36: =D36^2+2/D36 -> 3.8090327 | F36: =2*(D36-1/D36^2)*(_C10+2*_C20*(E36-3)+3*_C30*(E36-3)^2) -> 0.40764137 | H36: =(1-F36/B36)^2 -> 0.0077800163 | Q36: =(F36-B36)^2 -> 0.001091732 | S36: =ABS(F36-B36) -> 0.033041369
A37: 0.621 | B37: 0.3833 | D37: =A37+1 -> 1.621 | E37: =D37^2+2/D37 -> 3.8614473 | F37: =2*(D37-1/D37^2)*(_C10+2*_C20*(E37-3)+3*_C30*(E37-3)^2) -> 0.41715765 | H37: =(1-F37/B37)^2 -> 0.0078025414 | J37: The stress TU is the nominal, or engineering stress. For the case of uniaxial deformation, | Q37: =(F37-B37)^2 -> 0.0011463407 | S37: =ABS(F37-B37) -> 0.033857654
A38: 0.642 | B38: 0.3912 | D38: =A38+1 -> 1.642 | E38: =D38^2+2/D38 -> 3.9141908 | F38: =2*(D38-1/D38^2)*(_C10+2*_C20*(E38-3)+3*_C30*(E38-3)^2) -> 0.4263638 | H38: =(1-F38/B38)^2 -> 0.0080796737 | J38: the relationship between nominal stress and stretch is given by this equation: | Q38: =(F38-B38)^2 -> 0.0012364926 | S38: =ABS(F38-B38) -> 0.035163796
A39: 0.6631 | B39: 0.4001 | D39: =A39+1 -> 1.6631 | E39: =D39^2+2/D39 -> 3.9684751 | F39: =2*(D39-1/D39^2)*(_C10+2*_C20*(E39-3)+3*_C30*(E39-3)^2) -> 0.43550019 | H39: =(1-F39/B39)^2 -> 0.0078284173 | Q39: =(F39-B39)^2 -> 0.0012531731 | S39: =ABS(F39-B39) -> 0.035400185
A40: 0.6849 | B40: 0.4083 | D40: =A40+1 -> 1.6849 | E40: =D40^2+2/D40 -> 4.0259021 | F40: =2*(D40-1/D40^2)*(_C10+2*_C20*(E40-3)+3*_C30*(E40-3)^2) -> 0.44483965 | H40: =(1-F40/B40)^2 -> 0.0080088466 | Q40: =(F40-B40)^2 -> 0.0013351459 | S40: =ABS(F40-B40) -> 0.036539649
A41: 0.706 | B41: 0.4172 | D41: =A41+1 -> 1.706 | E41: =D41^2+2/D41 -> 4.0827689 | F41: =2*(D41-1/D41^2)*(_C10+2*_C20*(E41-3)+3*_C30*(E41-3)^2) -> 0.4538015 | H41: =(1-F41/B41)^2 -> 0.007696783 | Q41: =(F41-B41)^2 -> 0.00133967 | S41: =ABS(F41-B41) -> 0.036601503
A42: 0.7271 | B42: 0.4254 | D42: =A42+1 -> 1.7271 | E42: =D42^2+2/D42 -> 4.1408849 | F42: =2*(D42-1/D42^2)*(_C10+2*_C20*(E42-3)+3*_C30*(E42-3)^2) -> 0.46270586 | H42: =(1-F42/B42)^2 -> 0.0076905794 | Q42: =(F42-B42)^2 -> 0.0013917269 | S42: =ABS(F42-B42) -> 0.037305857
A43: 0.7483 | B43: 0.4338 | D43: =A43+1 -> 1.7483 | E43: =D43^2+2/D43 -> 4.2005213 | F43: =2*(D43-1/D43^2)*(_C10+2*_C20*(E43-3)+3*_C30*(E43-3)^2) -> 0.4716136 | H43: =(1-F43/B43)^2 -> 0.0075983077 | Q43: =(F43-B43)^2 -> 0.0014298681 | S43: =ABS(F43-B43) -> 0.037813596
A44: 0.7692 | B44: 0.4426 | D44: =A44+1 -> 1.7692 | E44: =D44^2+2/D44 -> 4.2605231 | F44: =2*(D44-1/D44^2)*(_C10+2*_C20*(E44-3)+3*_C30*(E44-3)^2) -> 0.48037609 | H44: =(1-F44/B44)^2 -> 0.0072846902 | K44: Taken from section 4.6.2 of the Abaqus Theory Manual | Q44: =(F44-B44)^2 -> 0.0014270326 | S44: =ABS(F44-B44) -> 0.037776086
A45: 0.7904 | B45: 0.451 | D45: =A45+1 -> 1.7904 | E45: =D45^2+2/D45 -> 4.322601 | F45: =2*(D45-1/D45^2)*(_C10+2*_C20*(E45-3)+3*_C30*(E45-3)^2) -> 0.4892643 | H45: =(1-F45/B45)^2 -> 0.0071983765 | Q45: =(F45-B45)^2 -> 0.001464157 | S45: =ABS(F45-B45) -> 0.038264304
A46: 0.8112 | B46: 0.4605 | D46: =A46+1 -> 1.8112 | E46: =D46^2+2/D46 -> 4.3846857 | F46: =2*(D46-1/D46^2)*(_C10+2*_C20*(E46-3)+3*_C30*(E46-3)^2) -> 0.49800392 | H46: =(1-F46/B46)^2 -> 0.0066327562 | Q46: =(F46-B46)^2 -> 0.0014065439 | S46: =ABS(F46-B46) -> 0.037503919
A47: 0.832 | B47: 0.4695 | D47: =A47+1 -> 1.832 | E47: =D47^2+2/D47 -> 4.4479271 | F47: =2*(D47-1/D47^2)*(_C10+2*_C20*(E47-3)+3*_C30*(E47-3)^2) -> 0.50678165 | H47: =(1-F47/B47)^2 -> 0.0063054938 | Q47: =(F47-B47)^2 -> 0.0013899216 | S47: =ABS(F47-B47) -> 0.037281652
A48: 0.8533 | B48: 0.479 | D48: =A48+1 -> 1.8533 | E48: =D48^2+2/D48 -> 4.513877 | F48: =2*(D48-1/D48^2)*(_C10+2*_C20*(E48-3)+3*_C30*(E48-3)^2) -> 0.51583012 | H48: =(1-F48/B48)^2 -> 0.0059120121 | Q48: =(F48-B48)^2 -> 0.001356458 | S48: =ABS(F48-B48) -> 0.036830123
A49: 0.873 | B49: 0.4887 | D49: =A49+1 -> 1.873 | E49: =D49^2+2/D49 -> 4.5759347 | F49: =2*(D49-1/D49^2)*(_C10+2*_C20*(E49-3)+3*_C30*(E49-3)^2) -> 0.52427088 | H49: =(1-F49/B49)^2 -> 0.0052979105 | Q49: =(F49-B49)^2 -> 0.0012652877 | S49: =ABS(F49-B49) -> 0.035570883
G51: TOTAL ERROR= | H51: =SUM(H8:H49) -> 0.39929441 | P51: TOTAL ERROR= | Q51: =SUM(Q8:Q49) -> 0.026196227 | S51: =SUM(S8:S49) -> 0.90341149

Sheet EB_S58
D1: Yeoh Calibration of an Elastomer, Equi-Biaxial Tension test data
A3: EQUI-BIAXIAL
A4: TEST DATA | H4: Relative | Q4: Absolute | S4: Absolute
A5: Eng. | B5: Eng. | E5: EquiBiaxial | F5: EquiBiaxial | H5: SQUARE | Q5: SQUARE | S5: value
A6: Strain | B6: Stress | D6: Stretch | E6: Invariant | F6: Calc Stress | H6: ERROR | Q6: ERROR | S6: ERROR
A7: 0 | B7: 0 | D7: =A7+1 -> 1 | E7: =2*D7^2+1/D7^4 -> 3 | F7: =2*(D7-1/D7^5)*(_C10+2*_C20*(E7-3)+3*_C30*(E7-3)^2) -> 0
A8: 0.0146 | B8: 0.0421 | D8: =A8+1 -> 1.0146 | E8: =2*D8^2+1/D8^4 -> 3.0024972 | F8: =2*(D8-1/D8^5)*(_C10+2*_C20*(E8-3)+3*_C30*(E8-3)^2) -> 0.030415052 | H8: =(1-F8/B8)^2 -> 0.077035226 | Q8: =(F8-B8)^2 -> 0.00013653801 | S8: =ABS(F8-B8) -> 0.011684948
A9: 0.0304 | B9: 0.0777 | D9: =A9+1 -> 1.0304 | E9: =2*D9^2+1/D9^4 -> 3.0105565 | F9: =2*(D9-1/D9^5)*(_C10+2*_C20*(E9-3)+3*_C30*(E9-3)^2) -> 0.060939642 | H9: =(1-F9/B9)^2 -> 0.046529089 | Q9: =(F9-B9)^2 -> 0.0002809096 | S9: =ABS(F9-B9) -> 0.016760358
A10: 0.0459 | B10: 0.1086 | D10: =A10+1 -> 1.0459 | E10: =2*D10^2+1/D10^4 -> 3.0234923 | F10: =2*(D10-1/D10^5)*(_C10+2*_C20*(E10-3)+3*_C30*(E10-3)^2) -> 0.088664515 | H10: =(1-F10/B10)^2 -> 0.033697211 | Q10: =(F10-B10)^2 -> 0.00039742356 | S10: =ABS(F10-B10) -> 0.019935485
A11: 0.0616 | B11: 0.1361 | D11: =A11+1 -> 1.0616 | E11: =2*D11^2+1/D11^4 -> 3.0413183 | F11: =2*(D11-1/D11^5)*(_C10+2*_C20*(E11-3)+3*_C30*(E11-3)^2) -> 0.11469038 | H11: =(1-F11/B11)^2 -> 0.02474581 | Q11: =(F11-B11)^2 -> 0.00045837183 | S11: =ABS(F11-B11) -> 0.02140962
A12: 0.077 | B12: 0.1605 | D12: =A12+1 -> 1.077 | E12: =2*D12^2+1/D12^4 -> 3.0631119 | F12: =2*(D12-1/D12^5)*(_C10+2*_C20*(E12-3)+3*_C30*(E12-3)^2) -> 0.13837294 | H12: =(1-F12/B12)^2 -> 0.019006295 | Q12: =(F12-B12)^2 -> 0.00048960691 | S12: =ABS(F12-B12) -> 0.022127063
A13: 0.0926 | B13: 0.1828 | D13: =A13+1 -> 1.0926 | E13: =2*D13^2+1/D13^4 -> 3.0892556 | F13: =2*(D13-1/D13^5)*(_C10+2*_C20*(E13-3)+3*_C30*(E13-3)^2) -> 0.16065301 | H13: =(1-F13/B13)^2 -> 0.014678337 | Q13: =(F13-B13)^2 -> 0.00049048897 | S13: =ABS(F13-B13) -> 0.022146985
A14: 0.1081 | B14: 0.2031 | D14: =A14+1 -> 1.1081 | E14: =2*D14^2+1/D14^4 -> 3.1190318 | F14: =2*(D14-1/D14^5)*(_C10+2*_C20*(E14-3)+3*_C30*(E14-3)^2) -> 0.18122668 | H14: =(1-F14/B14)^2 -> 0.011598705 | Q14: =(F14-B14)^2 -> 0.00047844205 | S14: =ABS(F14-B14) -> 0.021873318
A15: 0.1236 | B15: 0.2228 | D15: =A15+1 -> 1.1236 | E15: =2*D15^2+1/D15^4 -> 3.1523663 | F15: =2*(D15-1/D15^5)*(_C10+2*_C20*(E15-3)+3*_C30*(E15-3)^2) -> 0.2003719 | H15: =(1-F15/B15)^2 -> 0.010133384 | Q15: =(F15-B15)^2 -> 0.00050301956 | S15: =ABS(F15-B15) -> 0.022428098
A16: 0.1391 | B16: 0.2396 | D16: =A16+1 -> 1.1391 | E16: =2*D16^2+1/D16^4 -> 3.1890513 | F16: =2*(D16-1/D16^5)*(_C10+2*_C20*(E16-3)+3*_C30*(E16-3)^2) -> 0.21820874 | H16: =(1-F16/B16)^2 -> 0.007970749 | Q16: =(F16-B16)^2 -> 0.00045758603 | S16: =ABS(F16-B16) -> 0.021391261
A17: 0.1547 | B17: 0.2566 | D17: =A17+1 -> 1.1547 | E17: =2*D17^2+1/D17^4 -> 3.2291652 | F17: =2*(D17-1/D17^5)*(_C10+2*_C20*(E17-3)+3*_C30*(E17-3)^2) -> 0.23495204 | H17: =(1-F17/B17)^2 -> 0.0071173868 | Q17: =(F17-B17)^2 -> 0.00046863409 | S17: =ABS(F17-B17) -> 0.021647958
A18: 0.1705 | B18: 0.2713 | D18: =A18+1 -> 1.1705 | E18: =2*D18^2+1/D18^4 -> 3.2728793 | F18: =2*(D18-1/D18^5)*(_C10+2*_C20*(E18-3)+3*_C30*(E18-3)^2) -> 0.25078132 | H18: =(1-F18/B18)^2 -> 0.0057200442 | Q18: =(F18-B18)^2 -> 0.00042101636 | S18: =ABS(F18-B18) -> 0.020518683
A19: 0.1863 | B19: 0.2869 | D19: =A19+1 -> 1.1863 | E19: =2*D19^2+1/D19^4 -> 3.3195346 | F19: =2*(D19-1/D19^5)*(_C10+2*_C20*(E19-3)+3*_C30*(E19-3)^2) -> 0.26557542 | H19: =(1-F19/B19)^2 -> 0.0055245868 | Q19: =(F19-B19)^2 -> 0.00045473764 | S19: =ABS(F19-B19) -> 0.021324578
... A35: 0.4724 | B35: 0.4611 | D35: =A35+1 -> 1.4724 | E35: =2*D35^2+1/D35^4 -> 4.5486868 | F35: =2*(D35-1/D35^5)*(_C10+2*_C20*(E35-3)+3*_C30*(E35-3)^2) -> 0.43842691 | H35: =(1-F35/B35)^2 -> 0.0024178591 | Q35: =(F35-B35)^2 -> 0.00051406879 | S35: =ABS(F35-B35) -> 0.022673085
A36: 0.4923 | B36: 0.47 | D36: =A36+1 -> 1.4923 | E36: =2*D36^2+1/D36^4 -> 4.655558 | F36: =2*(D36-1/D36^5)*(_C10+2*_C20*(E36-3)+3*_C30*(E36-3)^2) -> 0.44818194 | H36: =(1-F36/B36)^2 -> 0.0021549462 | J36: The stress TB is the engineering stress. For the case of equibiaxial deformation, | Q36: =(F36-B36)^2 -> 0.00047602762 | S36: =ABS(F36-B36) -> 0.021818057
A37: 0.5123 | B37: 0.4802 | D37: =A37+1 -> 1.5123 | E37: =2*D37^2+1/D37^4 -> 4.7652851 | F37: =2*(D37-1/D37^5)*(_C10+2*_C20*(E37-3)+3*_C30*(E37-3)^2) -> 0.45814693 | H37: =(1-F37/B37)^2 -> 0.002109083 | J37: the relationship between nominal stress and stretch is given by this equation: | Q37: =(F37-B37)^2 -> 0.00048633775 | S37: =ABS(F37-B37) -> 0.022053067
A38: 0.5323 | B38: 0.4905 | D38: =A38+1 -> 1.5323 | E38: =2*D38^2+1/D38^4 -> 4.8772814 | F38: =2*(D38-1/D38^5)*(_C10+2*_C20*(E38-3)+3*_C30*(E38-3)^2) -> 0.468344 | H38: =(1-F38/B38)^2 -> 0.0020403498 | Q38: =(F38-B38)^2 -> 0.00049088827 | S38: =ABS(F38-B38) -> 0.022155999
A39: 0.5526 | B39: 0.4996 | D39: =A39+1 -> 1.5526 | E39: =2*D39^2+1/D39^4 -> 4.9932259 | F39: =2*(D39-1/D39^5)*(_C10+2*_C20*(E39-3)+3*_C30*(E39-3)^2) -> 0.47900267 | H39: =(1-F39/B39)^2 -> 0.0016997191 | Q39: =(F39-B39)^2 -> 0.00042425016 | S39: =ABS(F39-B39) -> 0.020597334
A40: 0.5732 | B40: 0.5114 | D40: =A40+1 -> 1.5732 | E40: =2*D40^2+1/D40^4 -> 5.1131706 | F40: =2*(D40-1/D40^5)*(_C10+2*_C20*(E40-3)+3*_C30*(E40-3)^2) -> 0.49020966 | H40: =(1-F40/B40)^2 -> 0.0017169374 | Q40: =(F40-B40)^2 -> 0.00044903057 | S40: =ABS(F40-B40) -> 0.021190342
A41: 0.5938 | B41: 0.5214 | D41: =A41+1 -> 1.5938 | E41: =2*D41^2+1/D41^4 -> 5.235373 | F41: =2*(D41-1/D41^5)*(_C10+2*_C20*(E41-3)+3*_C30*(E41-3)^2) -> 0.50188359 | H41: =(1-F41/B41)^2 -> 0.0014010638 | Q41: =(F41-B41)^2 -> 0.00038089036 | S41: =ABS(F41-B41) -> 0.019516413
A42: 0.6137 | B42: 0.5333 | D42: =A42+1 -> 1.6137 | E42: =2*D42^2+1/D42^4 -> 5.3555271 | F42: =2*(D42-1/D42^5)*(_C10+2*_C20*(E42-3)+3*_C30*(E42-3)^2) -> 0.51367273 | H42: =(1-F42/B42)^2 -> 0.001354493 | Q42: =(F42-B42)^2 -> 0.00038522985 | S42: =ABS(F42-B42) -> 0.019627273
A43: 0.6344 | B43: 0.5448 | D43: =A43+1 -> 1.6344 | E43: =2*D43^2+1/D43^4 -> 5.4826682 | F43: =2*(D43-1/D43^5)*(_C10+2*_C20*(E43-3)+3*_C30*(E43-3)^2) -> 0.52654073 | H43: =(1-F43/B43)^2 -> 0.001123292 | K43: Taken from section 4.6.2 of the Abaqus Theory Manual | Q43: =(F43-B43)^2 -> 0.00033340097 | S43: =ABS(F43-B43) -> 0.018259271
A44: 0.6551 | B44: 0.5566 | D44: =A44+1 -> 1.6551 | E44: =2*D44^2+1/D44^4 -> 5.611973 | F44: =2*(D44-1/D44^5)*(_C10+2*_C20*(E44-3)+3*_C30*(E44-3)^2) -> 0.54009806 | H44: =(1-F44/B44)^2 -> 0.00087898944 | Q44: =(F44-B44)^2 -> 0.00027231406 | S44: =ABS(F44-B44) -> 0.016501941
A45: 0.6755 | B45: 0.5683 | D45: =A45+1 -> 1.6755 | E45: =2*D45^2+1/D45^4 -> 5.741489 | F45: =2*(D45-1/D45^5)*(_C10+2*_C20*(E45-3)+3*_C30*(E45-3)^2) -> 0.55420484 | H45: =(1-F45/B45)^2 -> 0.00061515488 | Q45: =(F45-B45)^2 -> 0.00019867343 | S45: =ABS(F45-B45) -> 0.014095156
A46: 0.6962 | B46: 0.5803 | D46: =A46+1 -> 1.6962 | E46: =2*D46^2+1/D46^4 -> 5.8749958 | F46: =2*(D46-1/D46^5)*(_C10+2*_C20*(E46-3)+3*_C30*(E46-3)^2) -> 0.56934879 | H46: =(1-F46/B46)^2 -> 0.00035613864 | Q46: =(F46-B46)^2 -> 0.00011992901 | S46: =ABS(F46-B46) -> 0.01095121
A47: 0.7173 | B47: 0.5922 | D47: =A47+1 -> 1.7173 | E47: =2*D47^2+1/D47^4 -> 6.0132167 | F47: =2*(D47-1/D47^5)*(_C10+2*_C20*(E47-3)+3*_C30*(E47-3)^2) -> 0.5857219 | H47: =(1-F47/B47)^2 -> 0.00011966273 | Q47: =(F47-B47)^2 -> 4.1965819e-05 | S47: =ABS(F47-B47) -> 0.0064781031
A48: 0.7379 | B48: 0.607 | D48: =A48+1 -> 1.7379 | E48: =2*D48^2+1/D48^4 -> 6.1502156 | F48: =2*(D48-1/D48^5)*(_C10+2*_C20*(E48-3)+3*_C30*(E48-3)^2) -> 0.60269436 | H48: =(1-F48/B48)^2 -> 5.0315048e-05 | Q48: =(F48-B48)^2 -> 1.8538529e-05 | S48: =ABS(F48-B48) -> 0.0043056392
A49: 0.7586 | B49: 0.6181 | D49: =A49+1 -> 1.7586 | E49: =2*D49^2+1/D49^4 -> 6.2898998 | F49: =2*(D49-1/D49^5)*(_C10+2*_C20*(E49-3)+3*_C30*(E49-3)^2) -> 0.62080739 | H49: =(1-F49/B49)^2 -> 1.9186027e-05 | Q49: =(F49-B49)^2 -> 7.3299757e-06 | S49: =ABS(F49-B49) -> 0.0027073928
A50: 0.7796 | B50: 0.6345 | D50: =A50+1 -> 1.7796 | E50: =2*D50^2+1/D50^4 -> 6.4336558 | F50: =2*(D50-1/D50^5)*(_C10+2*_C20*(E50-3)+3*_C30*(E50-3)^2) -> 0.64034499 | H50: =(1-F50/B50)^2 -> 8.4860115e-05 | Q50: =(F50-B50)^2 -> 3.4163855e-05 | S50: =ABS(F50-B50) -> 0.0058449855
A51: 0.8005 | B51: 0.6487 | D51: =A51+1 -> 1.8005 | E51: =2*D51^2+1/D51^4 -> 6.5787546 | F51: =2*(D51-1/D51^5)*(_C10+2*_C20*(E51-3)+3*_C30*(E51-3)^2) -> 0.66103113 | H51: =(1-F51/B51)^2 -> 0.00036134144 | Q51: =(F51-B51)^2 -> 0.0001520567 | S51: =ABS(F51-B51) -> 0.012331127
A52: 0.8214 | B52: 0.6656 | D52: =A52+1 -> 1.8214 | E52: =2*D52^2+1/D52^4 -> 6.7258572 | F52: =2*(D52-1/D52^5)*(_C10+2*_C20*(E52-3)+3*_C30*(E52-3)^2) -> 0.68303659 | H52: =(1-F52/B52)^2 -> 0.00068627256 | Q52: =(F52-B52)^2 -> 0.00030403478 | S52: =ABS(F52-B52) -> 0.017436593
A53: 0.8419 | B53: 0.6839 | D53: =A53+1 -> 1.8419 | E53: =2*D53^2+1/D53^4 -> 6.8720744 | F53: =2*(D53-1/D53^5)*(_C10+2*_C20*(E53-3)+3*_C30*(E53-3)^2) -> 0.70598154 | H53: =(1-F53/B53)^2 -> 0.0010424942 | Q53: =(F53-B53)^2 -> 0.00048759457 | S53: =ABS(F53-B53) -> 0.022081544
A54: 0.8629 | B54: 0.7004 | D54: =A54+1 -> 1.8629 | E54: =2*D54^2+1/D54^4 -> 7.0238241 | F54: =2*(D54-1/D54^5)*(_C10+2*_C20*(E54-3)+3*_C30*(E54-3)^2) -> 0.73096583 | H54: =(1-F54/B54)^2 -> 0.0019044964 | Q54: =(F54-B54)^2 -> 0.00093427006 | S54: =ABS(F54-B54) -> 0.030565832
A55: 0.8837 | B55: 0.7191 | D55: =A55+1 -> 1.8837 | E55: =2*D55^2+1/D55^4 -> 7.1760756 | F55: =2*(D55-1/D55^5)*(_C10+2*_C20*(E55-3)+3*_C30*(E55-3)^2) -> 0.75727195 | H55: =(1-F55/B55)^2 -> 0.0028177995 | Q55: =(F55-B55)^2 -> 0.0014570977 | S55: =ABS(F55-B55) -> 0.038171949
A56: 0.904 | B56: 0.7394 | D56: =A56+1 -> 1.904 | E56: =2*D56^2+1/D56^4 -> 7.3265228 | F56: =2*(D56-1/D56^5)*(_C10+2*_C20*(E56-3)+3*_C30*(E56-3)^2) -> 0.78452382 | H56: =(1-F56/B56)^2 -> 0.0037243706 | Q56: =(F56-B56)^2 -> 0.0020361594 | S56: =ABS(F56-B56) -> 0.045123823
...

Sheet PT_S58
D1: Yeoh Calibration of an Elastomer, Planar Tension test data
A3: PLANAR
A4: TEST DATA | H4: Relative | Q4: Absolute | S4: Absolute
A5: Eng. | B5: Eng. | E5: Planar | F5: Planar | H5: SQUARE | Q5: SQUARE | S5: value
A6: Strain | B6: Stress | D6: Stretch | E6: Invariant | F6: Calc Stress | H6: ERROR | Q6: ERROR | S6: ERROR
A7: 0 | B7: 0 | D7: =A7+1 -> 1 | E7: =D7^2+1/D7^2+1 -> 3 | F7: =2*(D7-1/D7^3)*(_C10+2*_C20*(E7-3)+3*_C30*(E7-3)^2) -> 0
A8: 0.0204 | B8: 0.0369 | D8: =A8+1 -> 1.0204 | E8: =D8^2+1/D8^2+1 -> 3.0016315 | F8: =2*(D8-1/D8^3)*(_C10+2*_C20*(E8-3)+3*_C30*(E8-3)^2) -> 0.028501861 | H8: =(1-F8/B8)^2 -> 0.05179805 | Q8: =(F8-B8)^2 -> 7.0528743e-05 | S8: =ABS(F8-B8) -> 0.0083981393
A9: 0.0425 | B9: 0.0664 | D9: =A9+1 -> 1.0425 | E9: =D9^2+1/D9^2+1 -> 3.0069335 | F9: =2*(D9-1/D9^3)*(_C10+2*_C20*(E9-3)+3*_C30*(E9-3)^2) -> 0.057516366 | H9: =(1-F9/B9)^2 -> 0.017899676 | Q9: =(F9-B9)^2 -> 7.8918954e-05 | S9: =ABS(F9-B9) -> 0.0088836341
A10: 0.0637 | B10: 0.0928 | D10: =A10+1 -> 1.0637 | E10: =D10^2+1/D10^2+1 -> 3.0152733 | F10: =2*(D10-1/D10^3)*(_C10+2*_C20*(E10-3)+3*_C30*(E10-3)^2) -> 0.083678365 | H10: =(1-F10/B10)^2 -> 0.0096616074 | Q10: =(F10-B10)^2 -> 8.3204217e-05 | S10: =ABS(F10-B10) -> 0.0091216345
A11: 0.0844 | B11: 0.1174 | D11: =A11+1 -> 1.0844 | E11: =D11^2+1/D11^2+1 -> 3.0263189 | F11: =2*(D11-1/D11^3)*(_C10+2*_C20*(E11-3)+3*_C30*(E11-3)^2) -> 0.10777245 | H11: =(1-F11/B11)^2 -> 0.0067250441 | Q11: =(F11-B11)^2 -> 9.2689669e-05 | S11: =ABS(F11-B11) -> 0.0096275474
A12: 0.105 | B12: 0.1401 | D12: =A12+1 -> 1.105 | E12: =D12^2+1/D12^2+1 -> 3.0400091 | F12: =2*(D12-1/D12^3)*(_C10+2*_C20*(E12-3)+3*_C30*(E12-3)^2) -> 0.1304377 | H12: =(1-F12/B12)^2 -> 0.0047564662 | Q12: =(F12-B12)^2 -> 9.3359967e-05 | S12: =ABS(F12-B12) -> 0.0096622961
A13: 0.1271 | B13: 0.1615 | D13: =A13+1 -> 1.1271 | E13: =D13^2+1/D13^2+1 -> 3.0575363 | F13: =2*(D13-1/D13^3)*(_C10+2*_C20*(E13-3)+3*_C30*(E13-3)^2) -> 0.15341062 | H13: =(1-F13/B13)^2 -> 0.00250891 | Q13: =(F13-B13)^2 -> 6.5438019e-05 | S13: =ABS(F13-B13) -> 0.0080893769
A14: 0.148 | B14: 0.1816 | D14: =A14+1 -> 1.148 | E14: =D14^2+1/D14^2+1 -> 3.0766846 | F14: =2*(D14-1/D14^3)*(_C10+2*_C20*(E14-3)+3*_C30*(E14-3)^2) -> 0.17395565 | H14: =(1-F14/B14)^2 -> 0.0017719433 | Q14: =(F14-B14)^2 -> 5.8436137e-05 | S14: =ABS(F14-B14) -> 0.0076443533
A15: 0.1689 | B15: 0.2002 | D15: =A15+1 -> 1.1689 | E15: =D15^2+1/D15^2+1 -> 3.0982163 | F15: =2*(D15-1/D15^3)*(_C10+2*_C20*(E15-3)+3*_C30*(E15-3)^2) -> 0.19344062 | H15: =(1-F15/B15)^2 -> 0.0011399488 | Q15: =(F15-B15)^2 -> 4.5689192e-05 | S15: =ABS(F15-B15) -> 0.0067593781
A16: 0.1907 | B16: 0.218 | D16: =A16+1 -> 1.1907 | E16: =D16^2+1/D16^2+1 -> 3.1231013 | F16: =2*(D16-1/D16^3)*(_C10+2*_C20*(E16-3)+3*_C30*(E16-3)^2) -> 0.21271993 | H16: =(1-F16/B16)^2 -> 0.00058663253 | Q16: =(F16-B16)^2 -> 2.7879124e-05 | S16: =ABS(F16-B16) -> 0.0052800686
A17: 0.213 | B17: 0.235 | D17: =A17+1 -> 1.213 | E17: =D17^2+1/D17^2+1 -> 3.1510082 | F17: =2*(D17-1/D17^3)*(_C10+2*_C20*(E17-3)+3*_C30*(E17-3)^2) -> 0.23142154 | H17: =(1-F17/B17)^2 -> 0.00023187674 | Q17: =(F17-B17)^2 -> 1.2805393e-05 | S17: =ABS(F17-B17) -> 0.0035784623
A18: 0.2359 | B18: 0.251 | D18: =A18+1 -> 1.2359 | E18: =D18^2+1/D18^2+1 -> 3.1821352 | F18: =2*(D18-1/D18^3)*(_C10+2*_C20*(E18-3)+3*_C30*(E18-3)^2) -> 0.24963628 | H18: =(1-F18/B18)^2 -> 2.9519124e-05 | Q18: =(F18-B18)^2 -> 1.8597343e-06 | S18: =ABS(F18-B18) -> 0.0013637208
A19: 0.2572 | B19: 0.2663 | D19: =A19+1 -> 1.2572 | E19: =D19^2+1/D19^2+1 -> 3.2132423 | F19: =2*(D19-1/D19^3)*(_C10+2*_C20*(E19-3)+3*_C30*(E19-3)^2) -> 0.2657471 | H19: =(1-F19/B19)^2 -> 4.3106855e-06 | Q19: =(F19-B19)^2 -> 3.0569524e-07 | S19: =ABS(F19-B19) -> 0.00055289713
... A35: 0.6189 | B35: 0.4456 | D35: =A35+1 -> 1.6189 | E35: =D35^2+1/D35^2+1 -> 4.0023947 | F35: =2*(D35-1/D35^3)*(_C10+2*_C20*(E35-3)+3*_C30*(E35-3)^2) -> 0.4621563 | H35: =(1-F35/B35)^2 -> 0.0013804987 | Q35: =(F35-B35)^2 -> 0.00027411093 | S35: =ABS(F35-B35) -> 0.016556296
A36: 0.6421 | B36: 0.4552 | D36: =A36+1 -> 1.6421 | E36: =D36^2+1/D36^2+1 -> 4.0673446 | F36: =2*(D36-1/D36^3)*(_C10+2*_C20*(E36-3)+3*_C30*(E36-3)^2) -> 0.47200176 | H36: =(1-F36/B36)^2 -> 0.0013624007 | J36: The stress TS is the engineering stress. For the case of equibiaxial deformation, | Q36: =(F36-B36)^2 -> 0.00028229903 | S36: =ABS(F36-B36) -> 0.016801757
A37: 0.6636 | B37: 0.4645 | D37: =A37+1 -> 1.6636 | E37: =D37^2+1/D37^2+1 -> 4.1288934 | F37: =2*(D37-1/D37^3)*(_C10+2*_C20*(E37-3)+3*_C30*(E37-3)^2) -> 0.48102456 | H37: =(1-F37/B37)^2 -> 0.0012655767 | J37: the relationship between nominal stress and stretch is given by this equation: | Q37: =(F37-B37)^2 -> 0.00027306114 | S37: =ABS(F37-B37) -> 0.016524562
A38: 0.687 | B38: 0.4741 | D38: =A38+1 -> 1.687 | E38: =D38^2+1/D38^2+1 -> 4.1973432 | F38: =2*(D38-1/D38^3)*(_C10+2*_C20*(E38-3)+3*_C30*(E38-3)^2) -> 0.49076541 | H38: =(1-F38/B38)^2 -> 0.00123564 | Q38: =(F38-B38)^2 -> 0.0002777358 | S38: =ABS(F38-B38) -> 0.016665407
A39: 0.7094 | B39: 0.4836 | D39: =A39+1 -> 1.7094 | E39: =D39^2+1/D39^2+1 -> 4.264274 | F39: =2*(D39-1/D39^3)*(_C10+2*_C20*(E39-3)+3*_C30*(E39-3)^2) -> 0.50004239 | H39: =(1-F39/B39)^2 -> 0.0011559989 | Q39: =(F39-B39)^2 -> 0.00027035227 | S39: =ABS(F39-B39) -> 0.016442393
A40: 0.7325 | B40: 0.4933 | D40: =A40+1 -> 1.7325 | E40: =D40^2+1/D40^2+1 -> 4.3347168 | F40: =2*(D40-1/D40^3)*(_C10+2*_C20*(E40-3)+3*_C30*(E40-3)^2) -> 0.50959158 | H40: =(1-F40/B40)^2 -> 0.0010906967 | Q40: =(F40-B40)^2 -> 0.00026541547 | S40: =ABS(F40-B40) -> 0.016291577
A41: 0.7554 | B41: 0.5032 | D41: =A41+1 -> 1.7554 | E41: =D41^2+1/D41^2+1 -> 4.4059539 | F41: =2*(D41-1/D41^3)*(_C10+2*_C20*(E41-3)+3*_C30*(E41-3)^2) -> 0.51907102 | H41: =(1-F41/B41)^2 -> 0.00099478334 | Q41: =(F41-B41)^2 -> 0.00025188933 | S41: =ABS(F41-B41) -> 0.015871022
A42: 0.778 | B42: 0.5133 | D42: =A42+1 -> 1.778 | E42: =D42^2+1/D42^2+1 -> 4.4776112 | F42: =2*(D42-1/D42^3)*(_C10+2*_C20*(E42-3)+3*_C30*(E42-3)^2) -> 0.52846884 | H42: =(1-F42/B42)^2 -> 0.00087329701 | Q42: =(F42-B42)^2 -> 0.00023009358 | S42: =ABS(F42-B42) -> 0.015168836
A43: 0.8006 | B43: 0.5237 | D43: =A43+1 -> 1.8006 | E43: =D43^2+1/D43^2+1 -> 4.5505967 | F43: =2*(D43-1/D43^3)*(_C10+2*_C20*(E43-3)+3*_C30*(E43-3)^2) -> 0.53793839 | H43: =(1-F43/B43)^2 -> 0.0007391909 | K43: Taken from section 4.6.2 of the Abaqus Theory Manual | Q43: =(F43-B43)^2 -> 0.00020273175 | S43: =ABS(F43-B43) -> 0.01423839
A44: 0.8235 | B44: 0.5345 | D44: =A44+1 -> 1.8235 | E44: =D44^2+1/D44^2+1 -> 4.6258904 | F44: =2*(D44-1/D44^3)*(_C10+2*_C20*(E44-3)+3*_C30*(E44-3)^2) -> 0.5476369 | H44: =(1-F44/B44)^2 -> 0.00060407425 | Q44: =(F44-B44)^2 -> 0.00017257812 | S44: =ABS(F44-B44) -> 0.013136899
G46: TOTAL ERROR= | H46: =SUM(H8:H44) -> 0.11892217 | P46: TOTAL ERROR= | Q46: =SUM(Q3:Q44) -> 0.0048461689 | S46: =SUM(S3:S44) -> 0.38208629

Sheet just data
A1: UNIAXIAL | D1: EQUI-BIAXIAL | G1: PLANAR
A2: TEST DATA | D2: TEST DATA | G2: TEST DATA
A3: Eng. | B3: Eng. | D3: Eng. | E3: Eng. | G3: Eng. | H3: Eng.
A4: Strain | B4: Stress | D4: Strain | E4: Stress | G4: Strain | H4: Stress
A5: 0 | B5: 0 | D5: 0 | E5: 0 | G5: 0 | H5: 0
A6: 0.0186 | B6: 0.0281 | D6: 0.0146 | E6: 0.0421 | G6: 0.0204 | H6: 0.0369
A7: 0.0372 | B7: 0.0515 | D7: 0.0304 | E7: 0.0777 | G7: 0.0425 | H7: 0.0664
A8: 0.0575 | B8: 0.0716 | D8: 0.0459 | E8: 0.1086 | G8: 0.0637 | H8: 0.0928
A9: 0.0777 | B9: 0.0906 | D9: 0.0616 | E9: 0.1361 | G9: 0.0844 | H9: 0.1174
A10: 0.0974 | B10: 0.1085 | D10: 0.077 | E10: 0.1605 | G10: 0.105 | H10: 0.1401
A11: 0.1172 | B11: 0.1254 | D11: 0.0926 | E11: 0.1828 | G11: 0.1271 | H11: 0.1615
A12: 0.1374 | B12: 0.1414 | D12: 0.1081 | E12: 0.2031 | G12: 0.148 | H12: 0.1816
A13: 0.1581 | B13: 0.1566 | D13: 0.1236 | E13: 0.2228 | G13: 0.1689 | H13: 0.2002
A14: 0.1778 | B14: 0.1718 | D14: 0.1391 | E14: 0.2396 | G14: 0.1907 | H14: 0.218
A15: 0.1991 | B15: 0.1848 | D15: 0.1547 | E15: 0.2566 | G15: 0.213 | H15: 0.235
A16: 0.2202 | B16: 0.1985 | D16: 0.1705 | E16: 0.2713 | G16: 0.2359 | H16: 0.251
... A31: 0.5371 | B31: 0.3501 | D31: 0.4325 | E31: 0.4426 | G31: 0.5732 | H31: 0.4267
A32: 0.5575 | B32: 0.3583 | D32: 0.4525 | E32: 0.4508 | G32: 0.595 | H32: 0.4361 | J32: This is test data used in the SIMULIA course "Testing and Analysis of Elastomers" taught at the Axel Products test facility.
A33: 0.5787 | B33: 0.3666 | D33: 0.4724 | E33: 0.4611 | G33: 0.6189 | H33: 0.4456 | J33: All test data taken at 23 degrees C
A34: 0.5996 | B34: 0.3746 | D34: 0.4923 | E34: 0.47 | G34: 0.6421 | H34: 0.4552 | J34: www.axelproducts.com
A35: 0.621 | B35: 0.3833 | D35: 0.5123 | E35: 0.4802 | G35: 0.6636 | H35: 0.4645
A36: 0.642 | B36: 0.3912 | D36: 0.5323 | E36: 0.4905 | G36: 0.687 | H36: 0.4741 | J36: ST == Simple Tension (same as Uniaxial)
A37: 0.6631 | B37: 0.4001 | D37: 0.5526 | E37: 0.4996 | G37: 0.7094 | H37: 0.4836 | J37: EB == Equi-Biaxial
A38: 0.6849 | B38: 0.4083 | D38: 0.5732 | E38: 0.5114 | G38: 0.7325 | H38: 0.4933 | J38: PT == Planar Tension
A39: 0.706 | B39: 0.4172 | D39: 0.5938 | E39: 0.5214 | G39: 0.7554 | H39: 0.5032
A40: 0.7271 | B40: 0.4254 | D40: 0.6137 | E40: 0.5333 | G40: 0.778 | H40: 0.5133
A41: 0.7483 | B41: 0.4338 | D41: 0.6344 | E41: 0.5448 | G41: 0.8006 | H41: 0.5237
A42: 0.7692 | B42: 0.4426 | D42: 0.6551 | E42: 0.5566 | G42: 0.8235 | H42: 0.5345
A43: 0.7904 | B43: 0.451 | D43: 0.6755 | E43: 0.5683
A44: 0.8112 | B44: 0.4605 | D44: 0.6962 | E44: 0.5803
A45: 0.832 | B45: 0.4695 | D45: 0.7173 | E45: 0.5922
A46: 0.8533 | B46: 0.479 | D46: 0.7379 | E46: 0.607
A47: 0.873 | B47: 0.4887 | D47: 0.7586 | E47: 0.6181
D48: 0.7796 | E48: 0.6345
D49: 0.8005 | E49: 0.6487
D50: 0.8214 | E50: 0.6656
D51: 0.8419 | E51: 0.6839
D52: 0.8629 | E52: 0.7004
D53: 0.8837 | E53: 0.7191
D54: 0.904 | E54: 0.7394

Sheet from Abaqus
B1: copied and pasted from the Abaqus 6.13-1 .dat file
B3: UNIAXIAL | C3: TEST | D3: DATA
B5: NOMINAL | C5: NOMINAL | D5: NOMINAL
B6: STRAIN | C6: STRESS(TEST) | D6: STRESS(Abaqus)
B7: 0.0186 | C7: 0.0281 | D7: 0.020989
B8: 0.0372 | C8: 0.0515 | D8: 0.041216
B9: 0.0575 | C9: 0.0716 | D9: 0.062455
B10: 0.0777 | C10: 0.0906 | D10: 0.082761
B11: 0.0974 | C11: 0.1085 | D11: 0.1018
B12: 0.1172 | C12: 0.1254 | D12: 0.1202
B13: 0.1374 | C13: 0.1414 | D13: 0.1383
B14: 0.1581 | C14: 0.1566 | D14: 0.156
B15: 0.1778 | C15: 0.1718 | D15: 0.1723
B16: 0.1991 | C16: 0.1848 | D16: 0.1892
B17: 0.2202 | C17: 0.1985 | D17: 0.2052
B18: 0.2408 | C18: 0.211 | D18: 0.2203
... B48: 0.873 | C48: 0.4887 | D48: 0.5031
B51: BIAXIAL | C51: TEST | D51: DATA
B53: NOMINAL | C53: NOMINAL | D53: NOMINAL
B54: STRAIN | C54: STRESS(TEST) | D54: STRESS(Abaqus)
B55: 0.0146 | C55: 0.0421 | D55: 0.032366
B56: 0.0304 | C56: 0.0777 | D56: 0.064804
B57: 0.0459 | C57: 0.1086 | D57: 0.094183
B58: 0.0616 | C58: 0.1361 | D58: 0.1216
B59: 0.077 | C59: 0.1605 | D59: 0.1465
B60: 0.0926 | C60: 0.1828 | D60: 0.1697
B61: 0.1081 | C61: 0.2031 | D61: 0.1909
B62: 0.1236 | C62: 0.2228 | D62: 0.2105
B63: 0.1391 | C63: 0.2396 | D63: 0.2286
B64: 0.1547 | C64: 0.2566 | D64: 0.2453
B65: 0.1705 | C65: 0.2713 | D65: 0.2608
B66: 0.1863 | C66: 0.2869 | D66: 0.2752
... B103: 0.904 | C103: 0.7394 | D103: 0.8143
B106: PLANAR | C106: TEST | D106: DATA
B108: NOMINAL | C108: NOMINAL | D108: NOMINAL
B109: STRAIN | C109: STRESS(TEST) | D109: STRESS(Abaqus)
B110: 0.0204 | C110: 0.0369 | D110: 0.030333
B111: 0.0425 | C111: 0.0664 | D111: 0.061183
B112: 0.0637 | C112: 0.0928 | D112: 0.088949
B113: 0.0844 | C113: 0.1174 | D113: 0.1145
...
